Workbook

Sheet Liste Test
A1: Environnement : Chrome 143 > ou Firefox 145 >
A2: Exigence | B2: Nom | C2: Fonctionnalité | D2: Prérequis | E2: Étape à réaliser | F2: Résultat attendu | G2: Résultat | H2: Statut du test | I2: Priorité | J2: Commentaire
A3: Connexion | H3: =IF(COUNTIF(H$4:H$8,"OK") = COUNTA(H$4:H$8), "OK", IF(COUNTIF(H$4:H$8,"KO") > 0, "KO", "TODO")) -> OK
A4: Connexion | B4: CONNEXION-1 | C4: Connexion | D4: Ne pas être logué | E4: Lancer le site, sur la page principale, Ne pas être connecté | F4: L’utilisateur est automatiquement redirigé vers la page de connexion | G4: Passe sans poser de problème, la redirection est bien éffectué | H4: OK | I4: 1
A5: Connexion | B5: CONNEXION-2 | C5: Connexion avec succès de l’utilisateur | D5: Ne pas être logué | E5: Lancer le site, sur la page de login Ne pas être connecté et se connecter avec des identifiants utilisateur valide | F5: Redirection vers la page d’acceuil de l’utilisateur, il est connecté, on peut le voir avec le nom d’utilisateur en haut a droite | G5: Redirection vers la page d’acceuil de l’utilisateur | H5: OK | I5: 1
A6: Connexion | B6: CONNEXION-3 | C6: Connexion avec succès de l’administrateur | D6: Ne pas être logué | E6: Lancer le site, sur la page de login Ne pas être connecté et se connecter avec des identifiants administrateur valide | F6: Redirection vers la page d’acceuil de l’utilisateur, il est connecté, on peut le voir avec le nom d’utilisateur en haut a droite, de plus un bouton d’accès a l’interface administrateur devrais être visible | G6: Redirection vers la page d’acceuil de l’administrateur, le bouton de gestion de l’application est bien visible | H6: OK | I6: 1
A7: Connexion | B7: CONNEXION-4 | C7: Connexion érroné de l’utilisateur | D7: Ne pas être logué | E7: Lancer le site, sur la page de login Ne pas être connecté et se connecter avec des identifiants utilisateur invalide | F7: Un message d’erreur est affiché et l’identifiant/mot de passe est conservé dans les champs de saisies pour qu’il puissent être modifié de plus le nombre de tentative restante est affiché (au nombre de 5 au total) | G7: Il y a uniquement un message d’erreur qui est affiché mais les infos de connexions érroné sont bien conservé dans les champs de saisie | H7: OK | I7: 1 | J7: Fix réalisé pour empécher un rechargement de la page a chaque login érroné (ce qui supprimé les infos de login érroné)
A8: Connexion | B8: CONNEXION-5 | C8: L’utilisateur se connecte pour la première fois a son compte à l’aide des identifiants fourni pas l’administrateur | D8: Test Création d’un utilisateur nécéssaire en utilisant les mêmes identifiants | E8: Lancer le site sur la page de connexion et utiliser les identifiants d’un utilisateur existant. | F8: L’utilisateur est automatiquement redirigé vers la page d’acceuil.et il voit son nom en haut à droite de plus il lui est demander de modifier son mot de passe | G8: La redirection est correctement éfféctué | H8: OK | I8: 1
A9: Connexion | B9: CONNEXION-6 | C9: L’utilisateur est bloqué si il fait 5 tentative erroné | D9: Avoir fait 4 tentative erroné | E9: Sur la page de connexion pour un même e-mail valide faire 5 tentatives avec un mot de passe erroné | F9: L’utilisateur avec l’adresse e-mail indiqué est bloqué pendant 30 minutes et le bouton connexion deviens grisé, le temps restant du bloquage est affiché. | H9: OK | I9: 3
A10: Gestion utilisateurs | H10: =IF(COUNTIF(H$11:H$21,"OK") = COUNTA(H$11:H$21), "OK", IF(COUNTIF(H$11:H$21,"KO") > 0, "KO", "TODO")) -> KO
A11: Gestion utilisateurs | B11: USER-1 | C11: Création de l’utilisateur et retour des informations pour l’utilisateur | D11: Être logué en tant qu’administrateur | E11: Sur la page administrateur, cliqué sur le bouton créer un utilisateur, indiquer son e-mail valide et n’ont utilisé par un autre utilisateur | F11: Un mot de passe temporaire pour l’utilisateur est indiqué à l’administrateur, pour qu’il soit transmi a l’utilisateur | H11: KO | I11: 1 | J11: Le mot de passe temporaire n’est jamais renvoyé
A12: Gestion utilisateurs | B12: USER-2 | C12: L’administrateur supprime un utilisateur | D12: Être logué en tant qu’administrateur | E12: Sur le site, aller sur la page de gestion de l’administrateur dans la rubrique gestion des joueurs et supprimer un joueur existant en appuyant sur le profil d’un utilisateur et en cliquant ensuite sur modifier | F12: Un message indiquant que l’opération a bien pu être appliqué et l’administrateur est redirigé vers la liste des utilisateurs | H12: OK | I12: 2
A13: Gestion utilisateurs | B13: USER-3 | C13: Vérirfication de la validité du numéro de licence | D13: Être logué en tant qu’administrateur | E13: Sur la page administrateur, cliqué sur le bouton créer un utilisateur, indiquer son e-mail valide mais un numéro de licence invalide (ex : B2562530) | F13: Un message d’erreur est affiché indiquant que le numéro de licence est mal formaté | H13: OK | I13: 3
A14: Gestion utilisateurs | B14: USER-004 | C14: Verification du mot de passe | D14: Être logué en tant qu’administrateur | E14: Lancer le site, sur la page de création d’utilisateur Ne pas être connecté et indiquer des identifiants utilisateur valide et un mot de passe de moins de 12 caractères, le mot de passe tésté doit contenir des caractère spéciaux ( !, @, #, …) des chiffres, des majuscules, des minuscules, et ne doit pas contenir d’espace | F14: Erreur indiquant que le mot de passe contient trop peu de caractère | G14: Une erreur est bien affiché en informant l’utilisateur que son mot de passe doit contenir plus de caractère | H14: OK | I14: 4
A15: Gestion utilisateurs | B15: USER-5 | C15: Verification du mot de passe | D15: Être logué en tant qu’administrateur | E15: Lancer le site, sur la page de création d’utilisateur Ne pas être connecté et indiquer des identifiants utilisateur valide et un mot de passe de plus de 60 caractère, le mot de passe tésté doit contenir des caractère spéciaux ( !, @, #, …) des chiffres, des majuscules, des minuscules, et ne doit pas contenir d’espace | F15: Erreur indiquant que le mot de passe contient trop de caractère | G15: Une erreur est bien affiché en informant l’utilisateur que son mot de passe doit contenir moins de caractère | H15: OK | I15: 2
A16: Gestion utilisateurs | B16: USER-6 | C16: Verification du mot de passe | D16: Être logué en tant qu’administrateur | E16: Lancer le site, sur la page de création d’utilisateur Ne pas être connecté et indiquer des identifiants utilisateur valide et un mot de passe compris entre 12 et 60 caractère et contenir des chiffres, des majuscules, des minuscules, et ne doit pas contenir d’espace, le mot de passe tésté ne doit pas contenir des caractère spéciaux ( !, @, #, …). | F16: Erreur indiquant que le mot de passe contient pas de caractère spéciaux | G16: Une erreur est bien affiché en informant l’utilisateur que son mot de passe doit contenir moins de caractère | H16: OK | I16: 4
A17: Gestion utilisateurs | B17: USER-7 | C17: Verification du mot de passe | D17: Être logué en tant qu’administrateur | E17: Lancer le site, sur la page de création d’utilisateur Ne pas être connecté et indiquer des identifiants utilisateur valide et un mot de passe compris entre 12 et 60 caractère et contenir des caractère spéciaux ( !, @, #, …), des chiffres, des majuscules, des minuscules, et doit contenir un ou plusieurs espaces. | F17: Erreur indiquant que le mot de passe contient un espace | G17: Une erreur est bien affiché en informant l’utilisateur que son mot de passe doit contenir moins de caractère | H17: OK | I17: 4
A18: Gestion utilisateurs | B18: USER-8 | C18: Verification du mot de passe | D18: Être logué en tant qu’administrateur | E18: Lancer le site, sur la page de création d’utilisateur Ne pas être connecté et indiquer des identifiants utilisateur valide et un mot de passe compris entre 12 et 60 caractère et contenir des caractère spéciaux ( !, @, #, …), des chiffres, des minuscules, et ne contient pas d’espace, cependant le mot de passe contient aucune majuscule | F18: Erreur indiquant que le mot de passe contient aucune majuscule | G18: Une erreur est bien affiché en informant l’utilisateur que son mot de passe doit contenir moins de caractère | H18: OK | I18: 4
A19: Gestion utilisateurs | B19: USER-9 | C19: Verification du mot de passe | D19: Être logué en tant qu’administrateur | E19: Lancer le site, sur la page de création d’utilisateur Ne pas être connecté et indiquer des identifiants utilisateur valide et un mot de passe compris entre 12 et 60 caractère et contenir des caractère spéciaux ( !, @, #, …), des chiffres, des majuscules, et ne contient pas d’espace, cependant le mot de passe contient aucune minuscule | F19: Erreur indiquant que le mot de passe contient aucune minuscule | G19: Une erreur est bien affiché en informant l’utilisateur que son mot de passe doit contenir moins de caractère | H19: OK | I19: 4
A20: Gestion utilisateurs | B20: USER-10 | C20: Verification du mot de passe | D20: Être logué en tant qu’administrateur | E20: Lancer le site, sur la page de création d’utilisateur Ne pas être connecté et indiquer des identifiants utilisateur valide et un mot de passe compris entre 12 et 60 caractère et contenir des caractère spéciaux ( !, @, #, …), des minuscules et des majuscules, et ne contient pas d’espace, cependant le mot de passe contient aucun chiffre | F20: Erreur indiquant que le mot de passe contient aucun chiffre | G20: Une erreur est bien affiché en informant l’utilisateur que son mot de passe doit contenir moins de caractère | H20: OK | I20: 4
A21: Gestion utilisateurs | B21: USER-11 | C21: Verification de la différence entre l’ancien et le nouveau mot de passe | D21: Être logué en tant qu’utilisateur | E21: Sur la page de modification du mot de passe indiqué le mot de passe actuel et dans le champs pour le nouveau mot de passe indiqué aussi le mot de passe actuel. | F21: Erreur indiquant que les mots de passe sont identique | H21: NON APPLICABLE | I21: 4 | J21: Feature non codé
A22: Planning | H22: =IF(COUNTIF(H$23:H$30,"OK") = COUNTA(H$23:H$30), "OK", IF(COUNTIF(H$23:H$30,"KO") > 0, "KO", "TODO")) -> OK
A23: Planning | B23: PLANNING-1 | C23: Accéder a la page du planning si on est connecté | D23: Être logué en tant qu’utilisateur | E23: Sur la page d’acceuil de l’utilisateur accéder à l’onglet planning dans la barre de navigation | F23: L’utilisateur est redirigé vers la page planning | G23: L’utilisateur est bien redirigé | H23: OK | I23: 1
A24: Planning | B24: PLANNING-2 | C24: Accéder au planning sans avoir les permissions | D24: Ne pas être logué | E24: Sur la page de connexion dans la barre url, remplacer le /login par /planning | F24: L’utilisateur est automatiquement redirigé vers la page de connexion | G24: L’utilisateur est bien redirigé | H24: OK | I24: 1
A25: Planning | B25: PLANNING-3 | C25: Utilisation du filtre pour voir uniquement ses propres matches | D25: Être connecté en tant qu’utilisateur | E25: Sur la page du planning décocher l’option « Voir mes matches » | F25: L’utilisateur voit désormais l’ensembles des matches et plus seulement les siens, il peut a tout moment réappliquer le filtre | G25: Le filtre est bien appliqué et retiré a la demande | H25: OK | I25: 4
A26: Planning | B26: PLANNING-4 | C26: Pouvoir faire défiler les mois du planning | D26: Être connecté en tant qu’utilisateur | E26: Sur la page du planning appuyer sur le bouton pour le mois suivant | F26: L’utilisateur doit voir le mois suivant le mois courant | G26: Le mois suivant est bien affiché | H26: OK | I26: 3
A27: Planning | B27: PLANNING-5 | C27: Sélectionner une journée précise dans le calendrier et pouvoir voir les matches de cette journée en détails | D27: Être connecté en tant qu’utilisateur | E27: Sur la page planning, cliquer sur un jour avec une match. | F27: L’utilisateur voit désormais en haut le détails de la journée et l’ensemble des matches planifiés. | G27: Le détails des matches est bien visible | H27: OK | I27: 2
A28: Planning | B28: PLANNING-6 | C28: L’administrateur peut ajouter un événement à un jour précis | D28: Être connecté en tant qu’administrateur | E28: Sur la page planning, cliquer sur un jour, une pop up devrais apparaître et proposer de voir les événements ou d’en ajouter un, cliquer sur ce dernier. | F28: L’administrateur a accès a un formulaire pour créer l’événement. | H28: OK | I28: 2
A29: Planning | B29: PLANNING-7 | C29: Listes des informations pour une journée en particulier | D29: Être connecté en tant qu’utilisateur | E29: Être sur la page d’un jour en particulier dans la rubrique planning | F29: L’utilisateur voit la liste des événements leurs heures respective, les matches par événement, et les équipes pour chaque matches avec les filtres | H29: OK | I29: 2
A30: Planning | B30: PLANNING-8 | C30: Listes des informations pour une journée en particulier et possibilité de modification pour l’administrateur. | D30: Être connecté en tant qu’administrateur | E30: Sur le détails d’une journée dans le planning en tant qu’administrateur | F30: L’administrateur doit pouvoir modifier un événement (nom, heure) et le supprimer | H30: OK | I30: 2
A31: Événements | H31: =IF(COUNTIF(H$32:H$37,"OK") = COUNTA(H$32:H$37), "OK", IF(COUNTIF(H$32:H$37,"KO") > 0, "KO", "TODO")) -> OK
A32: Événements | B32: EVENT-1 | C32: L’administrateur doit pouvoir ajouter un événement en y spécifiant l’ensemble des informations | D32: Être connecté en tant qu’administrateur | E32: Sur la page planning, cliquer sur un jour puis sur le bouton ajouter un événement, ensuite remplir les champs date (mettre une date futur, ou aujourd’hui), l’heure (future si date = aujourd’hui), et y ajouter un match et une équipe | F32: Un nouvelle événement apparaît dans les événements planifié de la journée | H32: OK | I32: 2
A33: Événements | B33: EVENT-2 | C33: L’administrateur ajoute un événement avec une date passé | D33: Être connecté en tant qu’administrateur | E33: Sur la page planning, cliquer sur un jour puis sur le bouton ajouter un événement, ensuite remplir les champs date (mettre une date antérieur a la date actuel ou aujourd’hui, ou aujourd’hui), l’heure (passé si date = aujourd’hui), et y ajouter un match et une équipe, le test devra être fait avec une date antérieur et une heure antérieur uniquement | F33: Un message d’erreur est affiché en refusant de créer l’événement, le champ date doit être modifié | H33: OK | I33: 3
A34: Événements | B34: EVENT-3 | C34: L’administrateur ajoute un événement avec deux matches sur la même piste ce qui est interdit | D34: Être connecté en tant qu’administrateur | E34: Sur la page planning, cliquer sur un jour et ajouter un événement, ensuite indiquant un ensemble d’information valide excepté qu’un match est assigné sur une piste déjà assigné | F34: Un message d’erreur est affiché indiquant que le numéro de piste est déjà pris et l’utilisateur doit le changer | H34: OK | I34: 3
A35: Événements | B35: EVENT-4 | C35: Restriction dans le cas où l’équipe est en doublon dans un match | D35: Être connecté en tant qu’administrateur | E35: Sur la page planning, cliquer sur un jour et ajouter un événement, ensuite indiquant un ensemble d’information valide excepté qu’un match ou deux fois la même équipe est sélectionné | F35: Un message d’erreur est affiché, empêchant la validation du formulaire, et indiquant qu’une équipe ne peut pas s’affronter elle même. | H35: OK | I35: 3
A36: Événements | B36: EVENT-5 | C36: Restriction dans le cas où l’équipe est inscrite dans deux match en simultané | D36: Être connecté en tant qu’administrateur | E36: Sur la page planning, cliquer sur un jour et ajouter un événement, ensuite indiquant un ensemble d’information valide excepté que l’équipe assigné a un match est déjà assigné a un autre match en simultané | F36: Un message d’erreur est affiché, empêchant la validation du formulaire, et indiquant qu’une équipe ne peut pas effectuer deux matches en simultanés | H36: OK | I36: 3
A37: Événements | B37: EVENT-6 | C37: Insertion typique d’un événement avec plusieurs matches | D37: Être connecté en tant qu’administrateur | E37: Sur la page planning, cliquer sur un jour et ajouter un événement, ensuite indiquant un ensemble d’information valide et 3 matches (le maximum) | F37: L’événement est inséré correctement et apparaît dans le planning, on peut y voir 3 matches dans le détail de l’événement | H37: OK | I37: 2
A38: Match | H38: =IF(COUNTIF(H$39:H$53,"OK") = COUNTA(H$39:H$53), "OK", IF(COUNTIF(H$39:H$53,"KO") > 0, "KO", "TODO")) -> KO
A39: Match | B39: MATCH-1 | C39: Affichage les 30 prochains matchs | D39: Être connecté en tant qu’utilisateur | E39: Aller sur l’onglet Match | F39: L’utilisateur doit être redirigé vers la page des matches et voir les 30 prochains matches | H39: OK | I39: 1
A40: Match | B40: MATCH-2 | C40: Affichage des matchs pour l’administrateur | D40: Être connecté en tant qu’administrateur | E40: En etant connecté en tant qu’administrateur, aller dans l’onglet match | F40: L’administrateur a accès à l’ensemble des matches visible | H40: OK | I40: 3
...

Sheet Stat
A4: STATUT | B4: Quantité | I4: Priorité | J4: STATUT | K4: Quantité
A5: OK | B5: =COUNTIFS('Liste Test'!H:H,A5, 'Liste Test'!I:I, ">0") -> 61 | I5: 1 | J5: OK | K5: =COUNTIFS('Liste Test'!H:H,J5,'Liste Test'!I:I,I5) -> 15
A6: KO | B6: =COUNTIFS('Liste Test'!H:H,A6,'Liste Test'!I:I,">0") -> 11 | J6: KO | K6: =COUNTIFS('Liste Test'!H:H,J6,'Liste Test'!I:I,I5) -> 5
A7: TODO | B7: =COUNTIFS('Liste Test'!H:H,A7,'Liste Test'!I:I,">0") -> 0 | J7: TODO | K7: =COUNTIFS('Liste Test'!H:H,J7,'Liste Test'!I:I,I5) -> 0
A8: IN PROGRESS | B8: =COUNTIFS('Liste Test'!H:H,A8,'Liste Test'!I:I,">0") -> 0 | J8: IN PROGRESS | K8: =COUNTIFS('Liste Test'!H:H,J8,'Liste Test'!I:I,I5) -> 0
A9: NON APPLICABLE | B9: =COUNTIFS('Liste Test'!H:H,A9,'Liste Test'!I:I,">0") -> 6 | J9: NON APPLICABLE | K9: =COUNTIFS('Liste Test'!H:H,J9,'Liste Test'!I:I,I5) -> 0
I10: 2 | J10: OK | K10: =COUNTIFS('Liste Test'!H:H,J10,'Liste Test'!I:I,I10) -> 14
J11: KO | K11: =COUNTIFS('Liste Test'!H:H,J11,'Liste Test'!I:I,I10) -> 1
J12: TODO | K12: =COUNTIFS('Liste Test'!H:H,J12,'Liste Test'!I:I,I10) -> 0
J13: IN PROGRESS | K13: =COUNTIFS('Liste Test'!H:H,J13,'Liste Test'!I:I,I10) -> 0
J14: NON APPLICABLE | K14: =COUNTIFS('Liste Test'!H:H,J14,'Liste Test'!I:I,I10) -> 1
I15: 3 | J15: OK | K15: =COUNTIFS('Liste Test'!H:H,J15,'Liste Test'!I:I,I15) -> 21
J16: KO | K16: =COUNTIFS('Liste Test'!H:H,J16,'Liste Test'!I:I,I15) -> 4
J17: TODO | K17: =COUNTIFS('Liste Test'!H:H,J17,'Liste Test'!I:I,I15) -> 0
A18: Catégorie fonctionnel | B18: STATUT | C18: Quantité | E18: Catégorie fonctionnel | F18: STATUT | G18: Quantité | J18: IN PROGRESS | K18: =COUNTIFS('Liste Test'!H:H,J18,'Liste Test'!I:I,I15) -> 0
A19: Connexion | B19: OK | C19: =COUNTIFS('Liste Test'!H:H,B19,'Liste Test'!A:A,A$19,'Liste Test'!I:I, ">0") -> 6 | E19: Équipe | F19: OK | G19: =COUNTIFS('Liste Test'!H:H,F19,'Liste Test'!A:A,E$19,'Liste Test'!I:I, ">0") -> 6 | J19: NON APPLICABLE | K19: =COUNTIFS('Liste Test'!H:H,J19,'Liste Test'!I:I,I15) -> 1
B20: KO | C20: =COUNTIFS('Liste Test'!H:H,B20,'Liste Test'!A:A,A$19,'Liste Test'!I:I,">0") -> 0 | F20: KO | G20: =COUNTIFS('Liste Test'!H:H,F20,'Liste Test'!A:A,E$19,'Liste Test'!I:I,">0") -> 1 | I20: 4 | J20: OK | K20: =COUNTIFS('Liste Test'!H:H,J20,'Liste Test'!I:I,I20) -> 11
B21: TODO | C21: =COUNTIFS('Liste Test'!H:H,B21,'Liste Test'!A:A,A$19,'Liste Test'!I:I,">0") -> 0 | F21: TODO | G21: =COUNTIFS('Liste Test'!H:H,F21,'Liste Test'!A:A,E$19,'Liste Test'!I:I,">0") -> 0 | J21: KO | K21: =COUNTIFS('Liste Test'!H:H,J21,'Liste Test'!I:I,I20) -> 1
B22: IN PROGRESS | C22: =COUNTIFS('Liste Test'!H:H,B22,'Liste Test'!A:A,A$19,'Liste Test'!I:I,">0") -> 0 | F22: IN PROGRESS | G22: =COUNTIFS('Liste Test'!H:H,F22,'Liste Test'!A:A,E$19,'Liste Test'!I:I,">0") -> 0 | J22: TODO | K22: =COUNTIFS('Liste Test'!H:H,J22,'Liste Test'!I:I,I20) -> 0
B23: NON APPLICABLE | C23: =COUNTIFS('Liste Test'!H:H,B23,'Liste Test'!A:A,A$19,'Liste Test'!I:I,">0") -> 0 | F23: NON APPLICABLE | G23: =COUNTIFS('Liste Test'!H:H,F23,'Liste Test'!A:A,E$19,'Liste Test'!I:I,">0") -> 0 | J23: IN PROGRESS | K23: =COUNTIFS('Liste Test'!H:H,J23,'Liste Test'!I:I,I20) -> 0
A24: Gestion utilisateurs | B24: OK | C24: =COUNTIFS('Liste Test'!H:H,B24,'Liste Test'!A:A,A$24,'Liste Test'!I:I, ">0") -> 9 | E24: Poule | F24: OK | G24: =COUNTIFS('Liste Test'!H:H,F24,'Liste Test'!A:A,E$24,'Liste Test'!I:I, ">0") -> 4 | J24: NON APPLICABLE | K24: =COUNTIFS('Liste Test'!H:H,J24,'Liste Test'!I:I,I20) -> 4
B25: KO | C25: =COUNTIFS('Liste Test'!H:H,B25,'Liste Test'!A:A,A$24,'Liste Test'!I:I,">0") -> 1 | F25: KO | G25: =COUNTIFS('Liste Test'!H:H,F25,'Liste Test'!A:A,E$24,'Liste Test'!I:I,">0") -> 2
B26: TODO | C26: =COUNTIFS('Liste Test'!H:H,B26,'Liste Test'!A:A,A$24,'Liste Test'!I:I,">0") -> 0 | F26: TODO | G26: =COUNTIFS('Liste Test'!H:H,F26,'Liste Test'!A:A,E$24,'Liste Test'!I:I,">0") -> 0
B27: IN PROGRESS | C27: =COUNTIFS('Liste Test'!H:H,B27,'Liste Test'!A:A,A$24,'Liste Test'!I:I,">0") -> 0 | F27: IN PROGRESS | G27: =COUNTIFS('Liste Test'!H:H,F27,'Liste Test'!A:A,E$24,'Liste Test'!I:I,">0") -> 0
B28: NON APPLICABLE | C28: =COUNTIFS('Liste Test'!H:H,B28,'Liste Test'!A:A,A$24,'Liste Test'!I:I,">0") -> 1 | F28: NON APPLICABLE | G28: =COUNTIFS('Liste Test'!H:H,F28,'Liste Test'!A:A,E$24,'Liste Test'!I:I,">0") -> 1
A29: Planning | B29: OK | C29: =COUNTIFS('Liste Test'!H:H,B29,'Liste Test'!A:A,A$29,'Liste Test'!I:I, ">0") -> 8 | E29: Résultat | F29: OK | G29: =COUNTIFS('Liste Test'!H:H,F29,'Liste Test'!A:A,E$29,'Liste Test'!I:I, ">0") -> 6
B30: KO | C30: =COUNTIFS('Liste Test'!H:H,B30,'Liste Test'!A:A,A$29,'Liste Test'!I:I,">0") -> 0 | F30: KO | G30: =COUNTIFS('Liste Test'!H:H,F30,'Liste Test'!A:A,E$29,'Liste Test'!I:I,">0") -> 1
B31: TODO | C31: =COUNTIFS('Liste Test'!H:H,B31,'Liste Test'!A:A,A$29,'Liste Test'!I:I,">0") -> 0 | F31: TODO | G31: =COUNTIFS('Liste Test'!H:H,F31,'Liste Test'!A:A,E$29,'Liste Test'!I:I,">0") -> 0
B32: IN PROGRESS | C32: =COUNTIFS('Liste Test'!H:H,B32,'Liste Test'!A:A,A$29,'Liste Test'!I:I,">0") -> 0 | F32: IN PROGRESS | G32: =COUNTIFS('Liste Test'!H:H,F32,'Liste Test'!A:A,E$29,'Liste Test'!I:I,">0") -> 0
B33: NON APPLICABLE | C33: =COUNTIFS('Liste Test'!H:H,B33,'Liste Test'!A:A,A$29,'Liste Test'!I:I,">0") -> 0 | F33: NON APPLICABLE | G33: =COUNTIFS('Liste Test'!H:H,F33,'Liste Test'!A:A,E$29,'Liste Test'!I:I,">0") -> 0
A34: Événements | B34: OK | C34: =COUNTIFS('Liste Test'!H:H,B34,'Liste Test'!A:A,A$34,'Liste Test'!I:I, ">0") -> 6 | E34: Profil | F34: OK | G34: =COUNTIFS('Liste Test'!H:H,F34,'Liste Test'!A:A,E$34,'Liste Test'!I:I, ">0") -> 1
B35: KO | C35: =COUNTIFS('Liste Test'!H:H,B35,'Liste Test'!A:A,A$34,'Liste Test'!I:I,">0") -> 0 | F35: KO | G35: =COUNTIFS('Liste Test'!H:H,F35,'Liste Test'!A:A,E$34,'Liste Test'!I:I,">0") -> 3
B36: TODO | C36: =COUNTIFS('Liste Test'!H:H,B36,'Liste Test'!A:A,A$34,'Liste Test'!I:I,">0") -> 0 | F36: TODO | G36: =COUNTIFS('Liste Test'!H:H,F36,'Liste Test'!A:A,E$34,'Liste Test'!I:I,">0") -> 0
B37: IN PROGRESS | C37: =COUNTIFS('Liste Test'!H:H,B37,'Liste Test'!A:A,A$34,'Liste Test'!I:I,">0") -> 0 | F37: IN PROGRESS | G37: =COUNTIFS('Liste Test'!H:H,F37,'Liste Test'!A:A,E$34,'Liste Test'!I:I,">0") -> 0
B38: NON APPLICABLE | C38: =COUNTIFS('Liste Test'!H:H,B38,'Liste Test'!A:A,A$34,'Liste Test'!I:I,">0") -> 0 | F38: NON APPLICABLE | G38: =COUNTIFS('Liste Test'!H:H,F38,'Liste Test'!A:A,E$34,'Liste Test'!I:I,">0") -> 2
A39: Match | B39: OK | C39: =COUNTIFS('Liste Test'!H:H,B39,'Liste Test'!A:A,A$39,'Liste Test'!I:I, ">0") -> 10 | E39: Gestion des accès | F39: OK | G39: =COUNTIFS('Liste Test'!H:H,F39,'Liste Test'!A:A,E$39,'Liste Test'!I:I, ">0") -> 5
B40: KO | C40: =COUNTIFS('Liste Test'!H:H,B40,'Liste Test'!A:A,A$39,'Liste Test'!I:I,">0") -> 3 | F40: KO | G40: =COUNTIFS('Liste Test'!H:H,F40,'Liste Test'!A:A,E$39,'Liste Test'!I:I,">0") -> 0
B41: TODO | C41: =COUNTIFS('Liste Test'!H:H,B41,'Liste Test'!A:A,A$39,'Liste Test'!I:I,">0") -> 0 | F41: TODO | G41: =COUNTIFS('Liste Test'!H:H,F41,'Liste Test'!A:A,E$39,'Liste Test'!I:I,">0") -> 0
B42: IN PROGRESS | C42: =COUNTIFS('Liste Test'!H:H,B42,'Liste Test'!A:A,A$39,'Liste Test'!I:I,">0") -> 0 | F42: IN PROGRESS | G42: =COUNTIFS('Liste Test'!H:H,F42,'Liste Test'!A:A,E$39,'Liste Test'!I:I,">0") -> 0
B43: NON APPLICABLE | C43: =COUNTIFS('Liste Test'!H:H,B43,'Liste Test'!A:A,A$39,'Liste Test'!I:I,">0") -> 2 | F43: NON APPLICABLE | G43: =COUNTIFS('Liste Test'!H:H,F43,'Liste Test'!A:A,E$39,'Liste Test'!I:I,">0") -> 0
